[*] Start mutation process:
   - targets: stack.py
   - tests: ./ALL-SMART
[*] 3 tests passed:
   - test_stack_WHOLE_SUITE [0.15400 s]
   - test_stack_MOSA [0.04802 s]
   - test_stack_MIO [0.04767 s]
   - test_stack_DYNAMOSA [0.04871 s]
[*] Start mutants generation and execution:
   - [#   1] CDI stack: 
--------------------------------------------------------------------------------
  14:     If the stack is empty, attempts to call pop should raise an exception.
  15: 
  16:     '''
  17:     
- 18:     def __init__(self, data=None):
- 19:         '''Initialization.'''
- 20:         self._stack = LinkedList(data)
- 21:     
+ 18:     @classmethod
+ 19:     def __init__(self, data=None):
+ 20:         '''Initialization.'''
+ 21:         self._stack = LinkedList(data)
  22:     def push(self, val):
  23:         '''Add val to the stack.'''
  24:         self._stack.push(val)
  25:     
--------------------------------------------------------------------------------
INTERNALERROR> Traceback (most recent call last):
INTERNALERROR>   File "/home/lucca/lucca/lib/python3.10/site-packages/_pytest/main.py", line 283, in wrap_session
INTERNALERROR>     session.exitstatus = doit(config, session) or 0
INTERNALERROR>   File "/home/lucca/lucca/lib/python3.10/site-packages/_pytest/main.py", line 337, in _main
INTERNALERROR>     config.hook.pytest_runtestloop(session=session)
INTERNALERROR>   File "/home/lucca/lucca/lib/python3.10/site-packages/pluggy/_hooks.py", line 513, in __call__
INTERNALERROR>     return self._hookexec(self.name, self._hookimpls.copy(), kwargs, firstresult)
INTERNALERROR>   File "/home/lucca/lucca/lib/python3.10/site-packages/pluggy/_manager.py", line 120, in _hookexec
INTERNALERROR>     return self._inner_hookexec(hook_name, methods, kwargs, firstresult)
INTERNALERROR>   File "/home/lucca/lucca/lib/python3.10/site-packages/pluggy/_callers.py", line 139, in _multicall
INTERNALERROR>     raise exception.with_traceback(exception.__traceback__)
INTERNALERROR>   File "/home/lucca/lucca/lib/python3.10/site-packages/pluggy/_callers.py", line 122, in _multicall
INTERNALERROR>     teardown.throw(exception)  # type: ignore[union-attr]
INTERNALERROR>   File "/home/lucca/lucca/lib/python3.10/site-packages/_pytest/logging.py", line 803, in pytest_runtestloop
INTERNALERROR>     return (yield)  # Run all the tests.
INTERNALERROR>   File "/home/lucca/lucca/lib/python3.10/site-packages/pluggy/_callers.py", line 103, in _multicall
INTERNALERROR>     res = hook_impl.function(*args)
INTERNALERROR>   File "/home/lucca/lucca/lib/python3.10/site-packages/_pytest/main.py", line 362, in pytest_runtestloop
INTERNALERROR>     item.config.hook.pytest_runtest_protocol(item=item, nextitem=nextitem)
INTERNALERROR>   File "/home/lucca/lucca/lib/python3.10/site-packages/pluggy/_hooks.py", line 513, in __call__
INTERNALERROR>     return self._hookexec(self.name, self._hookimpls.copy(), kwargs, firstresult)
INTERNALERROR>   File "/home/lucca/lucca/lib/python3.10/site-packages/pluggy/_manager.py", line 120, in _hookexec
INTERNALERROR>     return self._inner_hookexec(hook_name, methods, kwargs, firstresult)
INTERNALERROR>   File "/home/lucca/lucca/lib/python3.10/site-packages/pluggy/_callers.py", line 182, in _multicall
INTERNALERROR>     return outcome.get_result()
INTERNALERROR>   File "/home/lucca/lucca/lib/python3.10/site-packages/pluggy/_result.py", line 100, in get_result
INTERNALERROR>     raise exc.with_traceback(exc.__traceback__)
INTERNALERROR>   File "/home/lucca/lucca/lib/python3.10/site-packages/pluggy/_callers.py", line 167, in _multicall
INTERNALERROR>     teardown.throw(outcome._exception)
INTERNALERROR>   File "/home/lucca/lucca/lib/python3.10/site-packages/_pytest/warnings.py", line 112, in pytest_runtest_protocol
INTERNALERROR>     return (yield)
INTERNALERROR>   File "/home/lucca/lucca/lib/python3.10/site-packages/pluggy/_callers.py", line 167, in _multicall
INTERNALERROR>     teardown.throw(outcome._exception)
INTERNALERROR>   File "/home/lucca/lucca/lib/python3.10/site-packages/_pytest/assertion/__init__.py", line 176, in pytest_runtest_protocol
INTERNALERROR>     return (yield)
INTERNALERROR>   File "/home/lucca/lucca/lib/python3.10/site-packages/pluggy/_callers.py", line 167, in _multicall
INTERNALERROR>     teardown.throw(outcome._exception)
INTERNALERROR>   File "/home/lucca/lucca/lib/python3.10/site-packages/_pytest/unittest.py", line 429, in pytest_runtest_protocol
INTERNALERROR>     res = yield
INTERNALERROR>   File "/home/lucca/lucca/lib/python3.10/site-packages/pluggy/_callers.py", line 167, in _multicall
INTERNALERROR>     teardown.throw(outcome._exception)
INTERNALERROR>   File "/home/lucca/lucca/lib/python3.10/site-packages/_pytest/faulthandler.py", line 88, in pytest_runtest_protocol
INTERNALERROR>     return (yield)
INTERNALERROR>   File "/home/lucca/lucca/lib/python3.10/site-packages/pluggy/_callers.py", line 103, in _multicall
INTERNALERROR>     res = hook_impl.function(*args)
INTERNALERROR>   File "/home/lucca/lucca/lib/python3.10/site-packages/_pytest/runner.py", line 113, in pytest_runtest_protocol
INTERNALERROR>     runtestprotocol(item, nextitem=nextitem)
INTERNALERROR>   File "/home/lucca/lucca/lib/python3.10/site-packages/_pytest/runner.py", line 132, in runtestprotocol
INTERNALERROR>     reports.append(call_and_report(item, "call", log))
INTERNALERROR>   File "/home/lucca/lucca/lib/python3.10/site-packages/_pytest/runner.py", line 246, in call_and_report
INTERNALERROR>     ihook.pytest_runtest_logreport(report=report)
INTERNALERROR>   File "/home/lucca/lucca/lib/python3.10/site-packages/pluggy/_hooks.py", line 513, in __call__
INTERNALERROR>     return self._hookexec(self.name, self._hookimpls.copy(), kwargs, firstresult)
INTERNALERROR>   File "/home/lucca/lucca/lib/python3.10/site-packages/pluggy/_manager.py", line 120, in _hookexec
INTERNALERROR>     return self._inner_hookexec(hook_name, methods, kwargs, firstresult)
INTERNALERROR>   File "/home/lucca/lucca/lib/python3.10/site-packages/pluggy/_callers.py", line 139, in _multicall
INTERNALERROR>     raise exception.with_traceback(exception.__traceback__)
INTERNALERROR>   File "/home/lucca/lucca/lib/python3.10/site-packages/pluggy/_callers.py", line 103, in _multicall
INTERNALERROR>     res = hook_impl.function(*args)
INTERNALERROR>   File "/home/lucca/lucca/lib/python3.10/site-packages/mutpy/test_runners/pytest_runner.py", line 28, in pytest_runtest_logreport
INTERNALERROR>     if 'TypeError' in report.longrepr.reprcrash.message:
INTERNALERROR> AttributeError: 'str' object has no attribute 'reprcrash'
[0.08163 s] survived
   - [#   2] CDI stack: 
--------------------------------------------------------------------------------
  18:     def __init__(self, data=None):
  19:         '''Initialization.'''
  20:         self._stack = LinkedList(data)
  21:     
- 22:     def push(self, val):
- 23:         '''Add val to the stack.'''
- 24:         self._stack.push(val)
- 25:     
+ 22:     @classmethod
+ 23:     def push(self, val):
+ 24:         '''Add val to the stack.'''
+ 25:         self._stack.push(val)
  26:     def pop(self):
  27:         '''Remove item off the stack.'''
  28:         self._stack.pop()
--------------------------------------------------------------------------------
[0.10928 s] survived
   - [#   3] CDI stack: 
--------------------------------------------------------------------------------
  22:     def push(self, val):
  23:         '''Add val to the stack.'''
  24:         self._stack.push(val)
  25:     
- 26:     def pop(self):
- 27:         '''Remove item off the stack.'''
- 28:         self._stack.pop()
+ 26:     @classmethod
+ 27:     def pop(self):
+ 28:         '''Remove item off the stack.'''
+ 29:         self._stack.pop()
--------------------------------------------------------------------------------
[0.10227 s] survived
   - [#   4] SDI stack: 
--------------------------------------------------------------------------------
  14:     If the stack is empty, attempts to call pop should raise an exception.
  15: 
  16:     '''
  17:     
- 18:     def __init__(self, data=None):
- 19:         '''Initialization.'''
- 20:         self._stack = LinkedList(data)
- 21:     
+ 18:     @staticmethod
+ 19:     def __init__(self, data=None):
+ 20:         '''Initialization.'''
+ 21:         self._stack = LinkedList(data)
  22:     def push(self, val):
  23:         '''Add val to the stack.'''
  24:         self._stack.push(val)
  25:     
--------------------------------------------------------------------------------
[0.06631 s] incompetent

TypeError: /home/lucca/teste/python_experiments2/stack/ALL-SMART/test_stack_DYNAMOSA.py:7: TypeError: Stack.__init__() missing 1 required positional argument: 'self'

   - [#   5] SDI stack: 
--------------------------------------------------------------------------------
  18:     def __init__(self, data=None):
  19:         '''Initialization.'''
  20:         self._stack = LinkedList(data)
  21:     
- 22:     def push(self, val):
- 23:         '''Add val to the stack.'''
- 24:         self._stack.push(val)
- 25:     
+ 22:     @staticmethod
+ 23:     def push(self, val):
+ 24:         '''Add val to the stack.'''
+ 25:         self._stack.push(val)
  26:     def pop(self):
  27:         '''Remove item off the stack.'''
  28:         self._stack.pop()
--------------------------------------------------------------------------------
[0.10418 s] survived
   - [#   6] SDI stack: 
--------------------------------------------------------------------------------
  22:     def push(self, val):
  23:         '''Add val to the stack.'''
  24:         self._stack.push(val)
  25:     
- 26:     def pop(self):
- 27:         '''Remove item off the stack.'''
- 28:         self._stack.pop()
+ 26:     @staticmethod
+ 27:     def pop(self):
+ 28:         '''Remove item off the stack.'''
+ 29:         self._stack.pop()
--------------------------------------------------------------------------------
[0.09748 s] survived
   - [#   7] SDL stack: 
--------------------------------------------------------------------------------
  16:     '''
  17:     
  18:     def __init__(self, data=None):
  19:         '''Initialization.'''
- 20:         self._stack = LinkedList(data)
+ 20:         pass
  21:     
  22:     def push(self, val):
  23:         '''Add val to the stack.'''
  24:         self._stack.push(val)
--------------------------------------------------------------------------------
[0.10490 s] survived
   - [#   8] SDL stack: 
--------------------------------------------------------------------------------
  20:         self._stack = LinkedList(data)
  21:     
  22:     def push(self, val):
  23:         '''Add val to the stack.'''
- 24:         self._stack.push(val)
+ 24:         pass
  25:     
  26:     def pop(self):
  27:         '''Remove item off the stack.'''
  28:         self._stack.pop()
--------------------------------------------------------------------------------
[0.10678 s] survived
   - [#   9] SDL stack: 
--------------------------------------------------------------------------------
  24:         self._stack.push(val)
  25:     
  26:     def pop(self):
  27:         '''Remove item off the stack.'''
- 28:         self._stack.pop()
+ 28:         pass
--------------------------------------------------------------------------------
INTERNALERROR> Traceback (most recent call last):
INTERNALERROR>   File "/home/lucca/lucca/lib/python3.10/site-packages/_pytest/main.py", line 283, in wrap_session
INTERNALERROR>     session.exitstatus = doit(config, session) or 0
INTERNALERROR>   File "/home/lucca/lucca/lib/python3.10/site-packages/_pytest/main.py", line 337, in _main
INTERNALERROR>     config.hook.pytest_runtestloop(session=session)
INTERNALERROR>   File "/home/lucca/lucca/lib/python3.10/site-packages/pluggy/_hooks.py", line 513, in __call__
INTERNALERROR>     return self._hookexec(self.name, self._hookimpls.copy(), kwargs, firstresult)
INTERNALERROR>   File "/home/lucca/lucca/lib/python3.10/site-packages/pluggy/_manager.py", line 120, in _hookexec
INTERNALERROR>     return self._inner_hookexec(hook_name, methods, kwargs, firstresult)
INTERNALERROR>   File "/home/lucca/lucca/lib/python3.10/site-packages/pluggy/_callers.py", line 139, in _multicall
INTERNALERROR>     raise exception.with_traceback(exception.__traceback__)
INTERNALERROR>   File "/home/lucca/lucca/lib/python3.10/site-packages/pluggy/_callers.py", line 122, in _multicall
INTERNALERROR>     teardown.throw(exception)  # type: ignore[union-attr]
INTERNALERROR>   File "/home/lucca/lucca/lib/python3.10/site-packages/_pytest/logging.py", line 803, in pytest_runtestloop
INTERNALERROR>     return (yield)  # Run all the tests.
INTERNALERROR>   File "/home/lucca/lucca/lib/python3.10/site-packages/pluggy/_callers.py", line 103, in _multicall
INTERNALERROR>     res = hook_impl.function(*args)
INTERNALERROR>   File "/home/lucca/lucca/lib/python3.10/site-packages/_pytest/main.py", line 362, in pytest_runtestloop
INTERNALERROR>     item.config.hook.pytest_runtest_protocol(item=item, nextitem=nextitem)
INTERNALERROR>   File "/home/lucca/lucca/lib/python3.10/site-packages/pluggy/_hooks.py", line 513, in __call__
INTERNALERROR>     return self._hookexec(self.name, self._hookimpls.copy(), kwargs, firstresult)
INTERNALERROR>   File "/home/lucca/lucca/lib/python3.10/site-packages/pluggy/_manager.py", line 120, in _hookexec
INTERNALERROR>     return self._inner_hookexec(hook_name, methods, kwargs, firstresult)
INTERNALERROR>   File "/home/lucca/lucca/lib/python3.10/site-packages/pluggy/_callers.py", line 182, in _multicall
INTERNALERROR>     return outcome.get_result()
INTERNALERROR>   File "/home/lucca/lucca/lib/python3.10/site-packages/pluggy/_result.py", line 100, in get_result
INTERNALERROR>     raise exc.with_traceback(exc.__traceback__)
INTERNALERROR>   File "/home/lucca/lucca/lib/python3.10/site-packages/pluggy/_callers.py", line 167, in _multicall
INTERNALERROR>     teardown.throw(outcome._exception)
INTERNALERROR>   File "/home/lucca/lucca/lib/python3.10/site-packages/_pytest/warnings.py", line 112, in pytest_runtest_protocol
INTERNALERROR>     return (yield)
INTERNALERROR>   File "/home/lucca/lucca/lib/python3.10/site-packages/pluggy/_callers.py", line 167, in _multicall
INTERNALERROR>     teardown.throw(outcome._exception)
INTERNALERROR>   File "/home/lucca/lucca/lib/python3.10/site-packages/_pytest/assertion/__init__.py", line 176, in pytest_runtest_protocol
INTERNALERROR>     return (yield)
INTERNALERROR>   File "/home/lucca/lucca/lib/python3.10/site-packages/pluggy/_callers.py", line 167, in _multicall
INTERNALERROR>     teardown.throw(outcome._exception)
INTERNALERROR>   File "/home/lucca/lucca/lib/python3.10/site-packages/_pytest/unittest.py", line 429, in pytest_runtest_protocol
INTERNALERROR>     res = yield
INTERNALERROR>   File "/home/lucca/lucca/lib/python3.10/site-packages/pluggy/_callers.py", line 167, in _multicall
INTERNALERROR>     teardown.throw(outcome._exception)
INTERNALERROR>   File "/home/lucca/lucca/lib/python3.10/site-packages/_pytest/faulthandler.py", line 88, in pytest_runtest_protocol
INTERNALERROR>     return (yield)
INTERNALERROR>   File "/home/lucca/lucca/lib/python3.10/site-packages/pluggy/_callers.py", line 103, in _multicall
INTERNALERROR>     res = hook_impl.function(*args)
INTERNALERROR>   File "/home/lucca/lucca/lib/python3.10/site-packages/_pytest/runner.py", line 113, in pytest_runtest_protocol
INTERNALERROR>     runtestprotocol(item, nextitem=nextitem)
INTERNALERROR>   File "/home/lucca/lucca/lib/python3.10/site-packages/_pytest/runner.py", line 132, in runtestprotocol
INTERNALERROR>     reports.append(call_and_report(item, "call", log))
INTERNALERROR>   File "/home/lucca/lucca/lib/python3.10/site-packages/_pytest/runner.py", line 246, in call_and_report
INTERNALERROR>     ihook.pytest_runtest_logreport(report=report)
INTERNALERROR>   File "/home/lucca/lucca/lib/python3.10/site-packages/pluggy/_hooks.py", line 513, in __call__
INTERNALERROR>     return self._hookexec(self.name, self._hookimpls.copy(), kwargs, firstresult)
INTERNALERROR>   File "/home/lucca/lucca/lib/python3.10/site-packages/pluggy/_manager.py", line 120, in _hookexec
INTERNALERROR>     return self._inner_hookexec(hook_name, methods, kwargs, firstresult)
INTERNALERROR>   File "/home/lucca/lucca/lib/python3.10/site-packages/pluggy/_callers.py", line 139, in _multicall
INTERNALERROR>     raise exception.with_traceback(exception.__traceback__)
INTERNALERROR>   File "/home/lucca/lucca/lib/python3.10/site-packages/pluggy/_callers.py", line 103, in _multicall
INTERNALERROR>     res = hook_impl.function(*args)
INTERNALERROR>   File "/home/lucca/lucca/lib/python3.10/site-packages/mutpy/test_runners/pytest_runner.py", line 28, in pytest_runtest_logreport
INTERNALERROR>     if 'TypeError' in report.longrepr.reprcrash.message:
INTERNALERROR> AttributeError: 'str' object has no attribute 'reprcrash'
[0.07014 s] survived
   - [#  10] SVD stack: 
--------------------------------------------------------------------------------
  16:     '''
  17:     
  18:     def __init__(self, data=None):
  19:         '''Initialization.'''
- 20:         self._stack = LinkedList(data)
+ 20:         _stack = LinkedList(data)
  21:     
  22:     def push(self, val):
  23:         '''Add val to the stack.'''
  24:         self._stack.push(val)
--------------------------------------------------------------------------------
[0.00000 s] incompetent

ValueError: expression must have Store context but has Load instead

   - [#  11] SVD stack: 
--------------------------------------------------------------------------------
  20:         self._stack = LinkedList(data)
  21:     
  22:     def push(self, val):
  23:         '''Add val to the stack.'''
- 24:         self._stack.push(val)
+ 24:         _stack.push(val)
  25:     
  26:     def pop(self):
  27:         '''Remove item off the stack.'''
  28:         self._stack.pop()
--------------------------------------------------------------------------------
[0.10373 s] survived
   - [#  12] SVD stack: 
--------------------------------------------------------------------------------
  24:         self._stack.push(val)
  25:     
  26:     def pop(self):
  27:         '''Remove item off the stack.'''
- 28:         self._stack.pop()
+ 28:         _stack.pop()
--------------------------------------------------------------------------------
[0.09749 s] survived
[*] Mutation score [1.48580 s]: 0.0%
   - all: 12
   - killed: 0 (0.0%)
   - survived: 10 (83.3%)
   - incompetent: 2 (16.7%)
   - timeout: 0 (0.0%)
